<?xml version="1.0" ?>
<!-- =================================================================================== -->
<!-- |    This document was autogenerated by xacro from /root/ros_ws/install/rbcar_model/share/rbcar_model/robots/rbcar2.urdf.xacro | -->
<!-- |    EDITING THIS FILE BY HAND IS NOT RECOMMENDED                                 | -->
<!-- =================================================================================== -->
<robot name="rbcar">
  <!-- ***************** -->
  <!-- Imported elements -->
  <!-- ***************** -->
  <gazebo reference="base_footprint">
    <material>Gazebo/Green</material>
  </gazebo>
  <!-- check -->
  <!--xacro:property name="suspension_joint_damping" value="0.2" />
  <xacro:property name="suspension_joint_friction" value="0.7" /-->
  <!-- check -->
  <!-- xacro:macro name="rubber_wheel" params="name parent *origin reflect hq" -->
  <!-- Import all available sensors -->
  <link name="world"/>
  <!-- This file unifies all sensors that can be used on simulation, defined as xacro:macros -->
  <!-- source en.wikipedia.org/wiki/List_of_moments_of_inertia-->
  <!-- <xacro:include filename="$(find robotnik_sensors)/urdf/gps/gps.urdf.xacro" /> -->
  <!-- <xacro:include filename="$(find robotnik_sensors)/urdf/gps/gps_with_mast.urdf.xacro" /> -->
  <!-- <xacro:include filename="$(find robotnik_sensors)/urdf/2d_lidar/hokuyo_utm30lx.urdf.xacro" /> -->
  <!-- <xacro:include filename="$(find robotnik_sensors)/urdf/2d_lidar/sick_outdoorscan3.urdf.xacro" /> -->
  <joint name="front_joint" type="fixed">
    <origin rpy="0.0 0.0 0.0" xyz="0.0 0.0 0.1"/>
    <parent link="world"/>
    <child link="front_link"/>
  </joint>
  <link name="front_link">
    <visual>
      <origin rpy="0 0 0" xyz="0 0 0"/>
      <geometry>
        <mesh filename="package://robotnik_sensors/meshes/depth/orbbec_astra/orbbec_astra.dae"/>
      </geometry>
    </visual>
    <collision>
      <origin rpy="0 0 0" xyz="-0.02 0 0.015"/>
      <geometry>
        <box size="0.042 0.155 0.03"/>
      </geometry>
    </collision>
    <inertial>
      <mass value="0.3"/>
      <origin xyz="0.0 0.0 0.0"/>
      <inertia ixx="0.0007031250000000001" ixy="0" ixz="0" iyy="6.25e-05" iyz="0" izz="0.000720625"/>
    </inertial>
  </link>
  <joint name="front_rgb_joint" type="fixed">
    <origin rpy="0.0 0.0 0.0" xyz="0.0 0.0125 0.0150"/>
    <parent link="front_link"/>
    <child link="front_rgb_frame"/>
  </joint>
  <link name="front_rgb_frame"/>
  <joint name="front_rgb_optical_joint" type="fixed">
    <origin rpy="-1.5707963267948966 0 -1.5707963267948966" xyz="0.0 0.0 0.0"/>
    <parent link="front_rgb_frame"/>
    <child link="front_rgb_optical_frame"/>
  </joint>
  <link name="front_rgb_optical_frame"/>
  <joint name="front_depth_joint" type="fixed">
    <origin rpy="0 0 0" xyz="0.0 0.0375 0.0150"/>
    <parent link="front_link"/>
    <child link="front_depth_frame"/>
  </joint>
  <link name="front_depth_frame"/>
  <joint name="front_depth_optical_joint" type="fixed">
    <origin rpy="-1.5707963267948966 0 -1.5707963267948966" xyz="0 0 0"/>
    <parent link="front_depth_frame"/>
    <child link="front_depth_optical_frame"/>
  </joint>
  <link name="front_depth_optical_frame"/>
  <gazebo reference="front_link">
    <sensor name="front_sensor" type="depth">
      <pose>0.0 0.0 0.0 0.0 0.0 0.0</pose>
      <visualize>false</visualize>
      <update_rate>30</update_rate>
      <camera>
        <horizontal_fov>1.0471975511965976</horizontal_fov>
        <vertical_fov>0.8639379797371931</vertical_fov>
        <image>
          <width>640</width>
          <height>480</height>
          <format>B8G8R8</format>
        </image>
        <clip>
          <near>0.05</near>
          <far>8.0</far>
        </clip>
        <noise>
          <type>gaussian</type>
          <mean>0.0</mean>
          <stddev>0.75</stddev>
        </noise>
      </camera>
      <plugin filename="libgazebo_ros_camera.so" name="front">
        <ros>
          <namespace></namespace>
          <remapping>~/image_raw:=~/rgb/image_raw</remapping>
          <remapping>~/camera_info:=~/rgb/camera_info</remapping>
          <remapping>~/points:=~/depth_registered/points</remapping>
          <remapping>~/depth/camera_info:=~/depth/camera_info</remapping>
          <remapping>~/depth/image_raw:=~/depth/image_raw</remapping>
        </ros>
        <camera_name>front</camera_name>
        <frame_name>front_rgb_optical_frame</frame_name>
        <min_depth>0.4</min_depth>
        <max_depth>8.0</max_depth>
      </plugin>
    </sensor>
  </gazebo>
  <!-- source en.wikipedia.org/wiki/List_of_moments_of_inertia-->
  <!-- ***************** -->
  <!-- Global parameters -->
  <!-- ***************** -->
  <!-- *************** -->
  <!-- Robot Elements -->
  <!-- *************** -->
  <link name="robot_base_footprint">
    <visual>
      <origin rpy="0 0 0" xyz="0 0 0"/>
      <geometry>
        <box size="0.001 0.001 0.001"/>
      </geometry>
    </visual>
  </link>
  <joint name="world_to_base" type="fixed">
    <parent link="world"/>
    <child link="robot_base_footprint"/>
    <origin rpy="0 0 0" xyz="0 0 0"/>
  </joint>
  <joint name="robot_base_footprint_joint" type="fixed">
    <origin rpy="0 0 0" xyz="0 0 0.3"/>
    <parent link="robot_base_footprint"/>
    <child link="robot_base_link"/>
  </joint>
  <!-- BASE_LINK -->
  <link name="robot_base_link">
    <inertial>
      <mass value="125.0"/>
      <origin xyz="0.917 0 0"/>
      <inertia ixx="1.391" ixy="0.004" ixz="0.0" iyy="6.853" iyz="0.0" izz="6.125"/>
    </inertial>
    <visual>
      <origin rpy="0 0 0" xyz="0.917 0 0"/>
      <geometry>
        <mesh filename="package://rbcar_model/meshes/bases/rbcar_chassis.stl"/>
      </geometry>
      <material name="gray">
        <color rgba="0.8 0.8 0.8 1"/>
      </material>
    </visual>
    <collision>
      <origin rpy="0 0 0" xyz="0.917 0 0"/>
      <geometry>
        <mesh filename="package://rbcar_model/meshes/bases/rbcar_chassis.stl"/>
      </geometry>
    </collision>
  </link>
  <!-- ROS 2 Control configuration -->
  <ros2_control name="GazeboSystem" type="system">
    <hardware>
      <plugin>gazebo_ros2_control/GazeboSystem</plugin>
    </hardware>
    <!-- Steering joints -->
    <joint name="robot_left_steering_joint">
      <command_interface name="position">
        <param name="min">-0.6</param>
        <param name="max">0.785398163</param>
      </command_interface>
      <state_interface name="position"/>
      <state_interface name="velocity"/>
    </joint>
    <joint name="robot_right_steering_joint">
      <command_interface name="position">
        <param name="min">-0.785398163</param>
        <param name="max">0.6</param>
      </command_interface>
      <state_interface name="position"/>
      <state_interface name="velocity"/>
    </joint>
    <!-- Front wheel joints -->
    <joint name="robot_left_front_axle">
      <!-- <command_interface name="velocity"/> -->
      <state_interface name="position"/>
      <state_interface name="velocity"/>
    </joint>
    <joint name="robot_right_front_axle">
      <!-- <command_interface name="velocity"/> -->
      <state_interface name="position"/>
      <state_interface name="velocity"/>
    </joint>
    <!-- Rear wheel joints -->
    <joint name="robot_left_rear_axle">
      <!-- <command_interface name="velocity"/> -->
      <state_interface name="position"/>
      <state_interface name="velocity"/>
    </joint>
    <joint name="robot_right_rear_axle">
      <!-- <command_interface name="velocity"/> -->
      <state_interface name="position"/>
      <state_interface name="velocity"/>
    </joint>
  </ros2_control>
  <gazebo>
    <!-- ROS 2 control plugin -->
    <plugin filename="libgazebo_ros2_control.so" name="gazebo_ros2_control">
      <parameters>/root/ros_ws/install/rbcar_model/share/rbcar_model/config/rbcar_controllers.yaml</parameters>
    </plugin>
  </gazebo>
  <joint name="robot_left_front_shock" type="fixed">
    <parent link="robot_base_link"/>
    <child link="robot_left_steering_link"/>
    <origin xyz="1.916615                    0.60901                    0.0"/>
  </joint>
  <link name="robot_left_steering_link">
    <inertial>
      <mass value="0.001"/>
      <inertia ixx="0.001" ixy="0" ixz="0" iyy="0.001" iyz="0" izz="0.001"/>
    </inertial>
  </link>
  <joint name="robot_left_steering_joint" type="revolute">
    <parent link="robot_left_steering_link"/>
    <child link="robot_left_front_axle_carrier"/>
    <axis xyz="0 0 1"/>
    <!-- this applies if we are setting the left wheel -->
    <limit effort="50" lower="-0.60822457" upper="0.785398163" velocity="25"/>
  </joint>
  <!-- ROS 2 transmission -->
  <transmission name="robot_left_steering_trans">
    <plugin>transmission_interface/SimpleTransmission</plugin>
    <actuator name="robot_left_steering_act" role="position"/>
    <joint name="robot_left_steering_joint" role="position">
      <!--<hardwareInterface>hardware_interface/EffortJointInterface</hardwareInterface>-->
      <mechanical_reduction>1.0</mechanical_reduction>
    </joint>
  </transmission>
  <gazebo reference="robot_left_steering_link">
    <material>Gazebo/Black</material>
  </gazebo>
  <link name="robot_left_front_axle_carrier">
    <inertial>
      <mass value="0.001"/>
      <inertia ixx="0.001" ixy="0" ixz="0" iyy="0.001" iyz="0" izz="0.001"/>
    </inertial>
  </link>
  <!-- The left and right axles have the same axis so that identical
         rotation values cause the wheels to rotate in the same direction. -->
  <joint name="robot_left_front_axle" type="continuous">
    <parent link="robot_left_front_axle_carrier"/>
    <child link="robot_left_front_wheel"/>
    <origin rpy="1.57079633 0 3.14159265"/>
    <axis xyz="0 0 1"/>
    <limit effort="204.95" velocity="39.02"/>
    <dynamics damping="0.2" friction="0.7"/>
  </joint>
  <!-- ROS 2 transmission -->
  <transmission name="robot_left_front_axle_trans">
    <plugin>transmission_interface/SimpleTransmission</plugin>
    <actuator name="robot_left_front_axle_act" role="velocity"/>
    <joint name="robot_left_front_axle" role="velocity">
      <mechanical_reduction>1.0</mechanical_reduction>
    </joint>
  </transmission>
  <gazebo reference="robot_left_front_axle_carrier">
    <material>Gazebo/Black</material>
  </gazebo>
  <link name="robot_left_front_wheel">
    <visual>
      <origin rpy="-1.57079633 0 3.14159265" xyz="0                        0                        -0.0825 "/>
      <geometry>
        <!--cylinder radius="${tire_dia / 2}" length="${tire_width}"/-->
        <!-- <mesh filename="package://rbcar_model/meshes/wheels/polaris/right_front_wheel.STL"/> -->
        <mesh filename="package://rbcar_model/meshes/wheels/rbcar_wheel.stl"/>
      </geometry>
      <material name="tire_mat"/>
    </visual>
    <collision>
      <origin xyz="0                      0                      -0.0025000000000000022"/>
      <geometry>
        <cylinder length="0.245" radius="0.3195"/>
      </geometry>
    </collision>
    <inertial>
      <mass value="8.0"/>
      <inertia ixx="0.27178966666666665" ixy="0" ixz="0" iyy="0.27178966666666665" iyz="0" izz="0.463546"/>
    </inertial>
  </link>
  <gazebo reference="robot_left_front_wheel">
    <material>Gazebo/Black</material>
  </gazebo>
  <joint name="robot_right_front_shock" type="fixed">
    <parent link="robot_base_link"/>
    <child link="robot_right_steering_link"/>
    <origin xyz="1.916615                    -0.60901                    0.0"/>
  </joint>
  <link name="robot_right_steering_link">
    <inertial>
      <mass value="0.001"/>
      <inertia ixx="0.001" ixy="0" ixz="0" iyy="0.001" iyz="0" izz="0.001"/>
    </inertial>
  </link>
  <joint name="robot_right_steering_joint" type="revolute">
    <parent link="robot_right_steering_link"/>
    <child link="robot_right_front_axle_carrier"/>
    <axis xyz="0 0 1"/>
    <!-- this applies if we are setting the right wheel -->
    <limit effort="50" lower="-0.785398163" upper="0.60822457" velocity="25"/>
  </joint>
  <!-- ROS 2 transmission -->
  <transmission name="robot_right_steering_trans">
    <plugin>transmission_interface/SimpleTransmission</plugin>
    <actuator name="robot_right_steering_act" role="position"/>
    <joint name="robot_right_steering_joint" role="position">
      <!--<hardwareInterface>hardware_interface/EffortJointInterface</hardwareInterface>-->
      <mechanical_reduction>1.0</mechanical_reduction>
    </joint>
  </transmission>
  <gazebo reference="robot_right_steering_link">
    <material>Gazebo/Black</material>
  </gazebo>
  <link name="robot_right_front_axle_carrier">
    <inertial>
      <mass value="0.001"/>
      <inertia ixx="0.001" ixy="0" ixz="0" iyy="0.001" iyz="0" izz="0.001"/>
    </inertial>
  </link>
  <!-- The left and right axles have the same axis so that identical
         rotation values cause the wheels to rotate in the same direction. -->
  <joint name="robot_right_front_axle" type="continuous">
    <parent link="robot_right_front_axle_carrier"/>
    <child link="robot_right_front_wheel"/>
    <origin rpy="1.57079633 0 3.14159265"/>
    <axis xyz="0 0 1"/>
    <limit effort="204.95" velocity="39.02"/>
    <dynamics damping="0.2" friction="0.7"/>
  </joint>
  <!-- ROS 2 transmission -->
  <transmission name="robot_right_front_axle_trans">
    <plugin>transmission_interface/SimpleTransmission</plugin>
    <actuator name="robot_right_front_axle_act" role="velocity"/>
    <joint name="robot_right_front_axle" role="velocity">
      <mechanical_reduction>1.0</mechanical_reduction>
    </joint>
  </transmission>
  <gazebo reference="robot_right_front_axle_carrier">
    <material>Gazebo/Black</material>
  </gazebo>
  <link name="robot_right_front_wheel">
    <visual>
      <origin rpy="1.57079633 0 3.14159265" xyz="0                        0                        0.0825 "/>
      <geometry>
        <!--cylinder radius="${tire_dia / 2}" length="${tire_width}"/-->
        <!-- <mesh filename="package://rbcar_model/meshes/wheels/polaris/right_front_wheel.STL"/> -->
        <mesh filename="package://rbcar_model/meshes/wheels/rbcar_wheel.stl"/>
      </geometry>
      <material name="tire_mat"/>
    </visual>
    <collision>
      <origin xyz="0                      0                      0.0025000000000000022"/>
      <geometry>
        <cylinder length="0.245" radius="0.3195"/>
      </geometry>
    </collision>
    <inertial>
      <mass value="8.0"/>
      <inertia ixx="0.27178966666666665" ixy="0" ixz="0" iyy="0.27178966666666665" iyz="0" izz="0.463546"/>
    </inertial>
  </link>
  <gazebo reference="robot_right_front_wheel">
    <material>Gazebo/Black</material>
  </gazebo>
  <joint name="robot_left_rear_shock" type="fixed">
    <parent link="robot_base_link"/>
    <child link="robot_left_rear_axle_carrier"/>
    <origin xyz="0.08338500000000004                    0.60901                    0.0"/>
  </joint>
  <link name="robot_left_rear_axle_carrier">
    <inertial>
      <mass value="0.001"/>
      <inertia ixx="0.001" ixy="0" ixz="0" iyy="0.001" iyz="0" izz="0.001"/>
    </inertial>
  </link>
  <!-- The left and right axles have the same axis so that identical
         rotation values cause the wheels to rotate in the same direction. -->
  <joint name="robot_left_rear_axle" type="continuous">
    <parent link="robot_left_rear_axle_carrier"/>
    <child link="robot_left_rear_wheel"/>
    <origin rpy="1.57079633 0 3.14159265"/>
    <axis xyz="0 0 1"/>
    <limit effort="204.95" velocity="39.02"/>
    <dynamics damping="0.2" friction="0.7"/>
  </joint>
  <!-- ROS 2 transmission -->
  <transmission name="robot_left_rear_axle_trans">
    <plugin>transmission_interface/SimpleTransmission</plugin>
    <actuator name="robot_left_rear_axle_act" role="velocity"/>
    <joint name="robot_left_rear_axle" role="velocity">
      <mechanical_reduction>1.0</mechanical_reduction>
    </joint>
  </transmission>
  <gazebo reference="robot_left_rear_axle_carrier">
    <material>Gazebo/Black</material>
  </gazebo>
  <link name="robot_left_rear_wheel">
    <visual>
      <origin rpy="-1.57079633 0 3.14159265" xyz="0                        0                        -0.0825 "/>
      <geometry>
        <!--cylinder radius="${tire_dia / 2}" length="${tire_width}"/-->
        <!-- <mesh filename="package://rbcar_model/meshes/wheels/polaris/right_front_wheel.STL"/> -->
        <mesh filename="package://rbcar_model/meshes/wheels/rbcar_wheel.stl"/>
      </geometry>
      <material name="tire_mat"/>
    </visual>
    <collision>
      <origin xyz="0                      0                      -0.0025000000000000022"/>
      <geometry>
        <cylinder length="0.245" radius="0.3195"/>
      </geometry>
    </collision>
    <inertial>
      <mass value="8.0"/>
      <inertia ixx="0.27178966666666665" ixy="0" ixz="0" iyy="0.27178966666666665" iyz="0" izz="0.463546"/>
    </inertial>
  </link>
  <gazebo reference="robot_left_rear_wheel">
    <material>Gazebo/Black</material>
  </gazebo>
  <joint name="robot_right_rear_shock" type="fixed">
    <parent link="robot_base_link"/>
    <child link="robot_right_rear_axle_carrier"/>
    <origin xyz="0.08338500000000004                    -0.60901                    0.0"/>
  </joint>
  <link name="robot_right_rear_axle_carrier">
    <inertial>
      <mass value="0.001"/>
      <inertia ixx="0.001" ixy="0" ixz="0" iyy="0.001" iyz="0" izz="0.001"/>
    </inertial>
  </link>
  <!-- The left and right axles have the same axis so that identical
         rotation values cause the wheels to rotate in the same direction. -->
  <joint name="robot_right_rear_axle" type="continuous">
    <parent link="robot_right_rear_axle_carrier"/>
    <child link="robot_right_rear_wheel"/>
    <origin rpy="1.57079633 0 3.14159265"/>
    <axis xyz="0 0 1"/>
    <limit effort="204.95" velocity="39.02"/>
    <dynamics damping="0.2" friction="0.7"/>
  </joint>
  <!-- ROS 2 transmission -->
  <transmission name="robot_right_rear_axle_trans">
    <plugin>transmission_interface/SimpleTransmission</plugin>
    <actuator name="robot_right_rear_axle_act" role="velocity"/>
    <joint name="robot_right_rear_axle" role="velocity">
      <mechanical_reduction>1.0</mechanical_reduction>
    </joint>
  </transmission>
  <gazebo reference="robot_right_rear_axle_carrier">
    <material>Gazebo/Black</material>
  </gazebo>
  <link name="robot_right_rear_wheel">
    <visual>
      <origin rpy="1.57079633 0 3.14159265" xyz="0                        0                        0.0825 "/>
      <geometry>
        <!--cylinder radius="${tire_dia / 2}" length="${tire_width}"/-->
        <!-- <mesh filename="package://rbcar_model/meshes/wheels/polaris/right_front_wheel.STL"/> -->
        <mesh filename="package://rbcar_model/meshes/wheels/rbcar_wheel.stl"/>
      </geometry>
      <material name="tire_mat"/>
    </visual>
    <collision>
      <origin xyz="0                      0                      0.0025000000000000022"/>
      <geometry>
        <cylinder length="0.245" radius="0.3195"/>
      </geometry>
    </collision>
    <inertial>
      <mass value="8.0"/>
      <inertia ixx="0.27178966666666665" ixy="0" ixz="0" iyy="0.27178966666666665" iyz="0" izz="0.463546"/>
    </inertial>
  </link>
  <gazebo reference="robot_right_rear_wheel">
    <material>Gazebo/Black</material>
  </gazebo>
  <!-- Sensors -->
  <!-- <xacro:sensor_rslidar_16 prefix="$(arg prefix)top_3d_laser" parent="$(arg prefix)base_link"
	gpu="$(arg gpu)">
	  <origin xyz="1.163 0.0 1.602" rpy="0 0.2637 0"/>
	</xacro:sensor_rslidar_16> -->
  <!-- <xacro:sensor_imu_hector prefix="$(arg prefix)imu" parent="$(arg prefix)base_link">
		<origin xyz="0.319 0.018 0.676" rpy="0 0 0"/>
	</xacro:sensor_imu_hector>

	<xacro:sensor_sick_outdoorscan3 frame_prefix="$(arg prefix)front_laser" parent="$(arg prefix)base_link"
	topic_prefix="front_laser" gpu="$(arg gpu)">
		<origin xyz="2.101 0 0.206" rpy="0 0 0"/>
	</xacro:sensor_sick_outdoorscan3>

	<xacro:sensor_hokuyo_utm30lx frame_prefix="$(arg prefix)rear_laser" parent="$(arg prefix)base_link"
	gpu="$(arg gpu)" topic_prefix="rear_laser">
      		<origin xyz="-0.42925 0.0 0.24674" rpy="0 0 ${PI}"/>
  	</xacro:sensor_hokuyo_utm30lx> -->
  <joint name="robot_gpsjoint" type="fixed">
    <origin rpy="0 0 0" xyz="0.491 0 1.503"/>
    <parent link="robot_base_link"/>
    <child link="robot_gpsbase_link"/>
  </joint>
  <link name="robot_gpsbase_link">
    <inertial>
      <origin rpy="0 0 0" xyz="0.0 0 0.015"/>
      <mass value="0.2"/>
      <inertia ixx="0.00012435" ixy="0" ixz="0" iyy="0.00012435" iyz="0" izz="0.00021870000000000003"/>
    </inertial>
    <visual>
      <origin rpy="0 0 0" xyz="0 0 0"/>
      <material name="gps_color">
        <color rgba="1 1 1 1"/>
      </material>
      <geometry>
        <mesh filename="package://robotnik_sensors/meshes/gps/antenna_3GO16.stl"/>
      </geometry>
    </visual>
    <collision>
      <origin rpy="0 0 0" xyz="0 0 0"/>
      <geometry>
        <mesh filename="package://robotnik_sensors/meshes/gps/antenna_3GO16.stl"/>
      </geometry>
    </collision>
  </link>
  <gazebo reference="robot_gpsbase_link">
    <material>Gazebo/White</material>
    <gravity>true</gravity>
  </gazebo>
  <gazebo reference="robot_gpsbase_link">
    <sensor name="robot_gpssensor" type="gps">
      <always_on>true</always_on>
      <update_rate>5.0</update_rate>
      <gps>
        <position_sensing>
          <horizontal>
            <noise type="gaussian">
              <mean>0.0</mean>
              <stddev>0.1</stddev>
            </noise>
          </horizontal>
          <vertical>
            <noise type="gaussian">
              <mean>0.0</mean>
              <stddev>0.1</stddev>
            </noise>
          </vertical>
        </position_sensing>
        <vertical_sensing>
          <horizontal>
            <noise type="gaussian">
              <mean>0.0</mean>
              <stddev>0.1</stddev>
            </noise>
          </horizontal>
          <vertical>
            <noise type="gaussian">
              <mean>0.0</mean>
              <stddev>0.1</stddev>
            </noise>
          </vertical>
        </vertical_sensing>
      </gps>
      <plugin filename="libgazebo_ros_gps_sensor.so" name="gps">
        <ros>
          <namespace>None</namespace>
          <remapping>~/out:=~/fix</remapping>
          <remapping>~/vel:=~/vel</remapping>
        </ros>
      </plugin>
    </sensor>
  </gazebo>
  <!-- Gazebo plugins -->
  <!--
	<gazebo>
		<plugin name="ground_truth_controller" filename="librobotnik_gazebo_ground_truth_odom.so">
			<alwaysOn>true</alwaysOn>
			<updateRate>50.0</updateRate>
			<bodyName>$(arg prefix)base_link</bodyName>
			<frameName>base_footprint_gt</frameName>
			<worldBodyName>world</worldBodyName>
			<worldFrameName>$(arg prefix)odom</worldFrameName>
			<topicName>odom_gt</topicName>
			<gaussianNoise>0.01</gaussianNoise>
			<xyzOffset>0.0 0 0</xyzOffset>
			<rpyOffset>0 0 0</rpyOffset>
			<applyOffset>False</applyOffset>
			<broadcastTF>True</broadcastTF>
		</plugin>
	</gazebo>

	<gazebo>
		<plugin name="gps_ground_truth_controller" filename="librobotnik_gazebo_ground_truth_odom.so">
			<alwaysOn>true</alwaysOn>
			<updateRate>50.0</updateRate>
			<bodyName>$(arg prefix)gps_base_link</bodyName>
			<frameName>gps_base_link_gt</frameName>
			<worldBodyName>world</worldBodyName>
			<worldFrameName>world</worldFrameName>
			<topicName>odom_gt</topicName>
			<gaussianNoise>0.01</gaussianNoise>
			<xyzOffset>0.0 0 0</xyzOffset>
			<rpyOffset>0 0 0</rpyOffset>
			<applyOffset>False</applyOffset>
			<broadcastTF>True</broadcastTF>
		</plugin>
	</gazebo>
	-->
</robot>
